<?xml version="1.0" encoding="utf-8"?>
<!--
  MuJoCo MJCF model for Lumi-Dex-11-R000-A1 Dexterous Hand (Right)
  ============================================================
  Converted from the Lumi-Dex-11 URDF package and README formulas.
-->

<mujoco model="Lumi-Dex-11-R000-A1">

  <compiler angle="radian" meshdir="../meshes" eulerseq="XYZ" autolimits="true"/>
  <option gravity="0 0 -9.81" timestep="0.002" iterations="100"/>

  <default>
    <joint type="hinge" damping="2.0" armature="0.01" frictionloss="0"/>
    <geom condim="4" friction="1.0 0.005 0.001" contype="0" conaffinity="0"/>
    <equality solref="0.004 1" solimp="0.9 0.99 0.001 0.5 2"/>
  </default>

  <asset>
    <mesh name="base_link" file="base_link.STL"/>
    <mesh name="finger11_link" file="finger11_link.STL"/>
    <mesh name="finger12_link" file="finger12_link.STL"/>
    <mesh name="finger13_link" file="finger13_link.STL"/>
    <mesh name="finger14_link" file="finger14_link.STL"/>
    <mesh name="finger21_link" file="finger21_link.STL"/>
    <mesh name="finger22_link" file="finger22_link.STL"/>
    <mesh name="finger23_link" file="finger23_link.STL"/>
    <mesh name="finger31_link" file="finger31_link.STL"/>
    <mesh name="finger32_link" file="finger32_link.STL"/>
    <mesh name="finger33_link" file="finger33_link.STL"/>
    <mesh name="finger41_link" file="finger41_link.STL"/>
    <mesh name="finger42_link" file="finger42_link.STL"/>
    <mesh name="finger43_link" file="finger43_link.STL"/>
    <mesh name="finger51_link" file="finger51_link.STL"/>
    <mesh name="finger52_link" file="finger52_link.STL"/>
    <mesh name="finger53_link" file="finger53_link.STL"/>
  </asset>

  <worldbody>

    <body name="base_link" pos="0 0 0">
      <geom name="base_link" type="mesh" mesh="base_link" rgba="1 1 1 1"/>
      <inertial pos="-0.0052741 0.002479 0.057207"
                mass="0.10866"
                fullinertia="8.6558E-05 5.5287E-05 4.1066E-05 1.592E-07 2.7057E-06 -4.058E-07"/>

      <!-- ===== 手指 1：大拇指 (Thumb) ===== -->
      <body name="finger11_link"
            pos="0.018 0.021747 0.043279"
            euler="-0.087266 0 0">
        <joint name="finger11" axis="0 0 -1" range="0 1.047198"/>
        <geom name="finger11_link" type="mesh" mesh="finger11_link" rgba="1 1 1 1"/>
        <inertial pos="0.0078225 0.0020462 -0.0025622"
                  mass="0.010254"
                  fullinertia="7.2142E-07 1.1141E-06 1.144E-06 -1.1025E-07 1.8578E-07 4.8596E-08"/>
        <body name="finger12_link"
              pos="0.018876 0.0049375 -0.0056093"
              euler="0 0.95149 0.25585">
          <joint name="finger12" axis="0 -1 0" range="0 0.523599"/>
          <geom name="finger12_link" type="mesh" mesh="finger12_link" rgba="1 1 1 1"/>
          <inertial pos="0.0014182 -1.2893E-06 0.024329"
                    mass="0.010145"
                    fullinertia="2.4795E-06 2.2943E-06 8.8906E-07 2.3633E-11 -9.1895E-08 4.4162E-11"/>
          <body name="finger13_link"
                pos="0 0 0.045"
                euler="0 0 0">
            <joint name="finger13" axis="0 -1 0" range="0.004592 0.594583"/>
            <geom name="finger13_link" type="mesh" mesh="finger13_link" rgba="1 1 1 1" contype="1" conaffinity="1"/>
            <inertial pos="0.0064864 -1.72E-06 0.014709"
                      mass="0.020548"
                      fullinertia="2.4642E-06 2.3555E-06 8.7678E-07 2.2654E-10 -1.276E-07 3.4328E-10"/>
            <body name="finger14_link"
                  pos="0 0 0"
                  euler="0 0 0">
              <geom name="finger14_link" type="mesh" mesh="finger14_link" rgba="0.2 0.2 0.2 1" contype="1" conaffinity="1"/>
              <inertial pos="0.0030983 8.624E-07 0.024752"
                        mass="0.00064654"
                        fullinertia="4.6206E-08 3.0972E-08 3.328E-08 -1.7511E-11 -7.0078E-09 3.3703E-12"/>
            </body>
          </body>
        </body>
      </body>

      <!-- ===== 手指 2：食指 (Index) ===== -->
      <body name="finger21_link"
            pos="-0.011581 0.031971 0.10003"
            euler="-0.052657 0.10625 -0.0055894">
        <joint name="finger21" axis="0 1 0" range="0 1.396263"/>
        <geom name="finger21_link" type="mesh" mesh="finger21_link" rgba="1 1 1 1"/>
        <inertial pos="-0.0017978 3.2789E-07 0.018686"
                  mass="0.0067143"
                  fullinertia="1.1951E-06 1.0688E-06 3.7304E-07 6.7451E-12 -4.4967E-09 -2.4168E-12"/>
        <body name="finger22_link"
              pos="0 0 0.035"
              euler="0 0 0">
          <joint name="finger22" axis="0 1 0" range="0.011072 1.687426"/>
          <geom name="finger22_link" type="mesh" mesh="finger22_link" rgba="1 1 1 1" contype="1" conaffinity="1"/>
          <inertial pos="-0.0019337 7.2998E-07 0.02175"
                    mass="0.014789"
                    fullinertia="1.4665E-06 1.4889E-06 3.5281E-07 1.1416E-11 -1.6584E-07 -9.2753E-11"/>
          <body name="finger23_link"
                pos="0 0 0"
                euler="0 0 0">
            <geom name="finger23_link" type="mesh" mesh="finger23_link" rgba="0.2 0.2 0.2 1" contype="1" conaffinity="1"/>
            <inertial pos="0.0027534 -5.1038E-07 0.027456"
                      mass="0.00083419"
                      fullinertia="1.0852E-07 9.6252E-08 2.404E-08 -2.4081E-13 -9.2843E-09 -2.9524E-12"/>
          </body>
        </body>
      </body>

      <!-- ===== 手指 3：中指 (Middle) ===== -->
      <body name="finger31_link"
            pos="-0.013501 0.0105 0.10286"
            euler="0 0.10214 0">
        <joint name="finger31" axis="0 1 0" range="0 1.396263"/>
        <geom name="finger31_link" type="mesh" mesh="finger31_link" rgba="1 1 1 1"/>
        <inertial pos="-0.0017978 3.3269E-07 0.018686"
                  mass="0.0067141"
                  fullinertia="1.1951E-06 1.0688E-06 3.7303E-07 1.1431E-11 -4.4917E-09 8.2241E-12"/>
        <body name="finger32_link"
              pos="0 0 0.035"
              euler="0 0 0">
          <joint name="finger32" axis="0 1 0" range="0.011072 1.687426"/>
          <geom name="finger32_link" type="mesh" mesh="finger32_link" rgba="1 1 1 1" contype="1" conaffinity="1"/>
          <inertial pos="-0.0021242 6.6141E-08 0.024943"
                    mass="0.017444"
                    fullinertia="4.1711E-06 4.1927E-06 4.4322E-07 1.8194E-11 -2.6488E-07 -1.6389E-11"/>
          <body name="finger33_link"
                pos="0 0 0"
                euler="0 0 0">
            <geom name="finger33_link" type="mesh" mesh="finger33_link" rgba="0.2 0.2 0.2 1" contype="1" conaffinity="1"/>
            <inertial pos="0.0025776 -4.8031E-07 0.03447"
                      mass="0.00083416"
                      fullinertia="1.0861E-07 9.6246E-08 2.3939E-08 1.3942E-12 -8.8309E-09 -5.9916E-13"/>
          </body>
        </body>
      </body>

      <!-- ===== 手指 4：无名指 (Ring) ===== -->
      <body name="finger41_link"
            pos="-0.015081 -0.010971 0.10183"
            euler="0.052889 0.14148 0.0074648">
        <joint name="finger41" axis="0 1 0" range="0 1.396263"/>
        <geom name="finger41_link" type="mesh" mesh="finger41_link" rgba="1 1 1 1"/>
        <inertial pos="-0.0017978 2.8835E-07 0.018686"
                  mass="0.006714"
                  fullinertia="1.1951E-06 1.0688E-06 3.7303E-07 1.5194E-11 -4.4902E-09 1.057E-11"/>
        <body name="finger42_link"
              pos="0 0 0.035"
              euler="0 0 0">
          <joint name="finger42" axis="0 1 0" range="0.011072 1.687426"/>
          <geom name="finger42_link" type="mesh" mesh="finger42_link" rgba="1 1 1 1" contype="1" conaffinity="1"/>
          <inertial pos="-0.00099481 6.0006E-07 0.021813"
                    mass="0.014788"
                    fullinertia="1.4501E-06 1.4888E-06 3.6915E-07 2.324E-11 -2.1315E-07 -8.582E-11"/>
          <body name="finger43_link"
                pos="0 0 0"
                euler="0 0 0">
            <geom name="finger43_link" type="mesh" mesh="finger43_link" rgba="0.2 0.2 0.2 1" contype="1" conaffinity="1"/>
            <inertial pos="0.0039336 -3.2576E-07 0.027311"
                      mass="0.0008342"
                      fullinertia="1.0756E-07 9.6251E-08 2.4997E-08 5.2726E-13 -1.2886E-08 -6.5627E-13"/>
          </body>
        </body>
      </body>

      <!-- ===== 手指 5：小拇指 (Pinky) ===== -->
      <body name="finger51_link"
            pos="-0.013081 -0.032156 0.097798"
            euler="0.078754 0.073706 0.0058113">
        <joint name="finger51" axis="0 1 0" range="0 1.396263"/>
        <geom name="finger51_link" type="mesh" mesh="finger51_link" rgba="1 1 1 1"/>
        <inertial pos="-0.0017978 4.0336E-07 0.018686"
                  mass="0.0067142"
                  fullinertia="1.1951E-06 1.0688E-06 3.7303E-07 9.6674E-12 -4.4947E-09 3.902E-12"/>
        <body name="finger52_link"
              pos="0 0 0.035"
              euler="0 0 0">
          <joint name="finger52" axis="0 1 0" range="0.011072 1.687426"/>
          <geom name="finger52_link" type="mesh" mesh="finger52_link" rgba="1 1 1 1" contype="1" conaffinity="1"/>
          <inertial pos="-0.0024432 3.1795E-07 0.016659"
                    mass="0.010445"
                    fullinertia="1.336E-06 1.3478E-06 2.4659E-07 2.6011E-11 -1.1818E-07 -5.5233E-12"/>
          <body name="finger53_link"
                pos="0 0 0"
                euler="0 0 0">
            <geom name="finger53_link" type="mesh" mesh="finger53_link" rgba="0.2 0.2 0.2 1" contype="1" conaffinity="1"/>
            <inertial pos="0.0021833 1.5926E-06 0.02278"
                      mass="0.00059177"
                      fullinertia="4.5328E-08 3.6598E-08 1.5894E-08 2.1034E-12 -3.5665E-09 -2.539E-12"/>
          </body>
        </body>
      </body>
    </body>

  </worldbody>

  <equality>
    <joint name="eq_thumb" joint1="finger13" joint2="finger12"
           polycoef="0.004592 0.8808 0.469825 0 0"/>
    <joint name="eq_index" joint1="finger22" joint2="finger21"
           polycoef="0.011072 0.9206 0.200535 0 0"/>
    <joint name="eq_middle" joint1="finger32" joint2="finger31"
           polycoef="0.011072 0.9206 0.200535 0 0"/>
    <joint name="eq_ring" joint1="finger42" joint2="finger41"
           polycoef="0.011072 0.9206 0.200535 0 0"/>
    <joint name="eq_pinky" joint1="finger52" joint2="finger51"
           polycoef="0.011072 0.9206 0.200535 0 0"/>
  </equality>

  <actuator>
    <position name="act_finger11" joint="finger11" kp="50" kv="2.0" ctrlrange="0 1.047198"/>
    <position name="act_finger12" joint="finger12" kp="50" kv="2.0" ctrlrange="0 0.523599"/>
    <position name="act_finger21" joint="finger21" kp="50" kv="2.0" ctrlrange="0 1.396263"/>
    <position name="act_finger31" joint="finger31" kp="50" kv="2.0" ctrlrange="0 1.396263"/>
    <position name="act_finger41" joint="finger41" kp="50" kv="2.0" ctrlrange="0 1.396263"/>
    <position name="act_finger51" joint="finger51" kp="50" kv="2.0" ctrlrange="0 1.396263"/>
  </actuator>

</mujoco>
