<?xml version='1.0' encoding='UTF-8'?>
<!-- This URDF was automatically created by SolidWorks to URDF Exporter! Originally created by Stephen Brawner (brawner@gmail.com) 
     Commit Version: 1.6.0-4-g7f85cfe  Build Version: 1.6.7995.38578
     For more information, please see http://wiki.ros.org/sw_urdf_exporter --><robot name="DH116S-R000-A1">
  <!--
    Authoritative kinematic description for this hand is the MJCF model.

    Independent DOFs: finger11, finger12, finger21, finger31, finger41, finger51
    Passive follower joints:
      finger13 follows finger12
      finger22 follows finger21
      finger32 follows finger31
      finger42 follows finger41
      finger52 follows finger51

    Note: URDF mimic supports only linear coupling:
      q_follower = multiplier * q_driver + offset
    The MJCF model uses quadratic coupling for the passive joints. The mimic tags
    below therefore preserve the dependency and use least-squares linear fits over
    each driver's configured motion range, but they do not exactly reproduce the
    nonlinear MJCF equality constraints.
  -->
  <link name="base_link">
    <inertial>
      <origin xyz="0.000384322111287069 0.00753084251208742 0.0472909739889326" rpy="0 0 0"/>
      <mass value="0.109379461925353"/>
      <inertia ixx="4.8658626062114E-05" ixy="1.90165367140657E-07" ixz="4.76749750234747E-07" iyy="6.96839906122602E-05" iyz="-2.36133057842731E-06" izz="3.07683899448741E-05"/>
    </inertial>
    <visual>
      <origin xyz="0 0 0" rpy="0 0 0"/>
      <geometry>
        <mesh filename="package://lhandpro_description/models/DH116S-R000-A1/meshes/base_link.STL"/>
      </geometry>
      <material name="">
        <color rgba="1 1 1 1"/>
      </material>
    </visual>
    <collision>
      <origin xyz="0 0 0" rpy="0 0 0"/>
      <geometry>
        <mesh filename="package://lhandpro_description/models/DH116S-R000-A1/meshes/base_link.STL"/>
      </geometry>
    </collision>
  </link>
  <link name="finger11_link">
    <inertial>
      <origin xyz="-0.000106936701499152 -0.00887532166965714 0.00188503573341194" rpy="0 0 0"/>
      <mass value="0.00704884300354655"/>
      <inertia ixx="9.65962069608261E-07" ixy="-1.44438396657121E-08" ixz="-2.78802353633112E-08" iyy="9.82359201731221E-07" iyz="1.16859938665557E-07" izz="2.90732053006428E-07"/>
    </inertial>
    <visual>
      <origin xyz="0 0 0" rpy="0 0 0"/>
      <geometry>
        <mesh filename="package://lhandpro_description/models/DH116S-R000-A1/meshes/finger11_link.STL"/>
      </geometry>
      <material name="">
        <color rgba="1 1 1 1"/>
      </material>
    </visual>
    <collision>
      <origin xyz="0 0 0" rpy="0 0 0"/>
      <geometry>
        <mesh filename="package://lhandpro_description/models/DH116S-R000-A1/meshes/finger11_link.STL"/>
      </geometry>
    </collision>
  </link>
  <joint name="finger11" type="revolute">
    <origin xyz="0.019011443942029 -0.00780399999999971 0.0343199999999998" rpy="0 0 1.4189526818714"/>
    <parent link="base_link"/>
    <child link="finger11_link"/>
    <axis xyz="0 0 -1"/>
    <limit lower="0" upper="1.588" effort="0" velocity="0"/>
  </joint>
  <link name="finger12_link">
    <inertial>
      <origin xyz="0.00575146979629403 -0.00980743444616855 0.019859071306553" rpy="0 0 0"/>
      <mass value="0.00572064501582461"/>
      <inertia ixx="1.07119834760592E-06" ixy="4.58213387989754E-08" ixz="-7.67707579266534E-08" iyy="1.23181109053526E-06" iyz="3.23507378708491E-07" izz="6.0079268566964E-07"/>
    </inertial>
    <visual>
      <origin xyz="0 0 0" rpy="0 0 0"/>
      <geometry>
        <mesh filename="package://lhandpro_description/models/DH116S-R000-A1/meshes/finger12_link.STL"/>
      </geometry>
      <material name="">
        <color rgba="1 1 1 1"/>
      </material>
    </visual>
    <collision>
      <origin xyz="0 0 0" rpy="0 0 0"/>
      <geometry>
        <mesh filename="package://lhandpro_description/models/DH116S-R000-A1/meshes/finger12_link.STL"/>
      </geometry>
    </collision>
  </link>
  <joint name="finger12" type="revolute">
    <origin xyz="-0.00241716818193387 -0.0149999999957004 0.00671430739411609" rpy="0.914460600969039 -0.26179938779915 0"/>
    <parent link="finger11_link"/>
    <child link="finger12_link"/>
    <axis xyz="-1 0 0"/>
    <limit lower="0" upper="1.030" effort="0" velocity="0"/>
  </joint>
  <link name="finger13_link">
    <inertial>
      <origin xyz="0.00252081313880359 -0.00372563202308732 0.00904163814125886" rpy="0 0 0"/>
      <mass value="0.00512347606012059"/>
      <inertia ixx="2.40947986098038E-07" ixy="-5.09796574066595E-10" ixz="-9.60704042330482E-10" iyy="3.07751181192004E-07" iyz="-7.35260411693152E-09" izz="1.61697663271219E-07"/>
    </inertial>
    <visual>
      <origin xyz="0 0 0" rpy="0 0 0"/>
      <geometry>
        <mesh filename="package://lhandpro_description/models/DH116S-R000-A1/meshes/finger13_link.STL"/>
      </geometry>
      <material name="">
        <color rgba="1 1 1 1"/>
      </material>
    </visual>
    <collision>
      <origin xyz="0 0 0" rpy="0 0 0"/>
      <geometry>
        <mesh filename="package://lhandpro_description/models/DH116S-R000-A1/meshes/finger13_link.STL"/>
      </geometry>
    </collision>
  </link>
  <joint name="finger13" type="revolute">
    <origin xyz="0.00598654106733671 -0.0125165261747051 0.0381626484720598" rpy="0.382919042912385 0.147573481949468 0.0154304498115495"/>
    <parent link="finger12_link"/>
    <child link="finger13_link"/>
    <axis xyz="-1 0 0"/>
    <limit lower="0" upper="1.13" effort="0" velocity="0"/>
    <mimic joint="finger12" multiplier="0.88178789" offset="-0.00697725445"/>
  </joint>
  <link name="finger14_link">
    <inertial>
      <origin xyz="0.00249769126018826 0.00167067101210644 0.0123801371744446" rpy="0 0 0"/>
      <mass value="0.00240482348656883"/>
      <inertia ixx="6.51224324821768E-08" ixy="-2.76696868457692E-10" ixz="-6.12678170657889E-10" iyy="9.9767942266961E-08" iyz="3.06755746735259E-09" izz="5.5208299164458E-08"/>
    </inertial>
    <visual>
      <origin xyz="0 0 0" rpy="0 0 0"/>
      <geometry>
        <mesh filename="package://lhandpro_description/models/DH116S-R000-A1/meshes/finger14_link.STL"/>
      </geometry>
      <material name="">
        <color rgba="0.2 0.2 0.2 1"/>
      </material>
    </visual>
    <collision>
      <origin xyz="0 0 0" rpy="0 0 0"/>
      <geometry>
        <mesh filename="package://lhandpro_description/models/DH116S-R000-A1/meshes/finger14_link.STL"/>
      </geometry>
    </collision>
  </link>
  <joint name="finger14" type="fixed">
    <origin xyz="0 0 0" rpy="0 0 0"/>
    <parent link="finger13_link"/>
    <child link="finger14_link"/>
    <axis xyz="0 0 0"/>
  </joint>
  <link name="finger21_link">
    <inertial>
      <origin xyz="0.00027210041910733 0.00170234735088368 0.014516323212758" rpy="0 0 0"/>
      <mass value="0.00393774528740839"/>
      <inertia ixx="3.16719166363702E-07" ixy="4.75695190346559E-09" ixz="1.33068275020846E-09" iyy="3.45533063039298E-07" iyz="7.7985196786372E-09" izz="1.51382459897184E-07"/>
    </inertial>
    <visual>
      <origin xyz="0 0 0" rpy="0 0 0"/>
      <geometry>
        <mesh filename="package://lhandpro_description/models/DH116S-R000-A1/meshes/finger21_link.STL"/>
      </geometry>
      <material name="">
        <color rgba="1 1 1 1"/>
      </material>
    </visual>
    <collision>
      <origin xyz="0 0 0" rpy="0 0 0"/>
      <geometry>
        <mesh filename="package://lhandpro_description/models/DH116S-R000-A1/meshes/finger21_link.STL"/>
      </geometry>
    </collision>
  </link>
  <joint name="finger21" type="revolute">
    <origin xyz="0.0262687686016299 0.00528244145664834 0.0838772330726273" rpy="0.184030828348921 0.0900710961718212 0"/>
    <parent link="base_link"/>
    <child link="finger21_link"/>
    <axis xyz="1 0 0"/>
    <limit lower="0" upper="1.257" effort="0" velocity="0"/>
  </joint>
  <link name="finger22_link">
    <inertial>
      <origin xyz="0.000180892622891587 0.00133699393436336 0.010912976228776" rpy="0 0 0"/>
      <mass value="0.00359509305446838"/>
      <inertia ixx="3.71495920772452E-07" ixy="3.3566423592835E-10" ixz="8.81868087157963E-09" iyy="3.74339102526511E-07" iyz="4.09550241976548E-08" izz="6.27179802580373E-08"/>
    </inertial>
    <visual>
      <origin xyz="0 0 0" rpy="0 0 0"/>
      <geometry>
        <mesh filename="package://lhandpro_description/models/DH116S-R000-A1/meshes/finger22_link.STL"/>
      </geometry>
      <material name="">
        <color rgba="1 1 1 1"/>
      </material>
    </visual>
    <collision>
      <origin xyz="0 0 0" rpy="0 0 0"/>
      <geometry>
        <mesh filename="package://lhandpro_description/models/DH116S-R000-A1/meshes/finger22_link.STL"/>
      </geometry>
    </collision>
  </link>
  <joint name="finger22" type="revolute">
    <origin xyz="0 0 0.028026675184573" rpy="0 0 0"/>
    <parent link="finger21_link"/>
    <child link="finger22_link"/>
    <axis xyz="1 0 0"/>
    <limit lower="0" upper="1.75" effort="0" velocity="0"/>
    <mimic joint="finger21" multiplier="1.36723967" offset="-0.0628270617"/>
  </joint>
  <link name="finger23_link">
    <inertial>
      <origin xyz="-0.000690109619396834 -0.00377783340062988 0.0191163501361598" rpy="0 0 0"/>
      <mass value="0.00194916130998001"/>
      <inertia ixx="9.25442673743886E-08" ixy="3.79093542922402E-10" ixz="3.55204790224285E-09" iyy="9.46455434630362E-08" iyz="2.17891055188829E-08" izz="3.02508825822761E-08"/>
    </inertial>
    <visual>
      <origin xyz="0 0 0" rpy="0 0 0"/>
      <geometry>
        <mesh filename="package://lhandpro_description/models/DH116S-R000-A1/meshes/finger23_link.STL"/>
      </geometry>
      <material name="">
        <color rgba="0.2 0.2 0.2 1"/>
      </material>
    </visual>
    <collision>
      <origin xyz="0 0 0" rpy="0 0 0"/>
      <geometry>
        <mesh filename="package://lhandpro_description/models/DH116S-R000-A1/meshes/finger23_link.STL"/>
      </geometry>
    </collision>
  </link>
  <joint name="finger23" type="fixed">
    <origin xyz="0 0 0" rpy="0 0 0"/>
    <parent link="finger22_link"/>
    <child link="finger23_link"/>
    <axis xyz="0 0 0"/>
  </joint>
  <link name="finger31_link">
    <inertial>
      <origin xyz="-2.41743304470188E-06 0.0016881536103133 0.0166092629083552" rpy="0 0 0"/>
      <mass value="0.00465632374460654"/>
      <inertia ixx="4.64032038497059E-07" ixy="-6.14756143609671E-11" ixz="5.30642140220418E-11" iyy="4.96217078056825E-07" iyz="1.19847357277137E-08" izz="1.78406731079551E-07"/>
    </inertial>
    <visual>
      <origin xyz="0 0 0" rpy="0 0 0"/>
      <geometry>
        <mesh filename="package://lhandpro_description/models/DH116S-R000-A1/meshes/finger31_link.STL"/>
      </geometry>
      <material name="">
        <color rgba="1 1 1 1"/>
      </material>
    </visual>
    <collision>
      <origin xyz="0 0 0" rpy="0 0 0"/>
      <geometry>
        <mesh filename="package://lhandpro_description/models/DH116S-R000-A1/meshes/finger31_link.STL"/>
      </geometry>
    </collision>
  </link>
  <joint name="finger31" type="revolute">
    <origin xyz="0.00874401205559361 0.00650966935499851 0.0881661201014335" rpy="0.175821944347936 0.05205044550937 -0.0495268334341439"/>
    <parent link="base_link"/>
    <child link="finger31_link"/>
    <axis xyz="1 0 0"/>
    <limit lower="0" upper="1.257" effort="0" velocity="0"/>
  </joint>
  <link name="finger32_link">
    <inertial>
      <origin xyz="-4.52052482557974E-07 0.000239188481448136 0.0125647103929899" rpy="0 0 0"/>
      <mass value="0.00396485659955852"/>
      <inertia ixx="5.13613810914939E-07" ixy="-3.89316581101276E-10" ixz="1.51691231313048E-09" iyy="5.04420042058448E-07" iyz="9.32849272033081E-08" izz="8.36320010149996E-08"/>
    </inertial>
    <visual>
      <origin xyz="0 0 0" rpy="0 0 0"/>
      <geometry>
        <mesh filename="package://lhandpro_description/models/DH116S-R000-A1/meshes/finger32_link.STL"/>
      </geometry>
      <material name="">
        <color rgba="1 1 1 1"/>
      </material>
    </visual>
    <collision>
      <origin xyz="0 0 0" rpy="0 0 0"/>
      <geometry>
        <mesh filename="package://lhandpro_description/models/DH116S-R000-A1/meshes/finger32_link.STL"/>
      </geometry>
    </collision>
  </link>
  <joint name="finger32" type="revolute">
    <origin xyz="0 -0.000265259842373017 0.0325298807757662" rpy="0 0 0"/>
    <parent link="finger31_link"/>
    <child link="finger32_link"/>
    <axis xyz="1 0 0"/>
    <limit lower="0" upper="1.75" effort="0" velocity="0"/>
    <mimic joint="finger31" multiplier="1.39585814" offset="-0.0787255295"/>
  </joint>
  <link name="finger33_link">
    <inertial>
      <origin xyz="1.11963736759702E-06 -0.00561969015110605 0.021082467343861" rpy="0 0 0"/>
      <mass value="0.00227280089263279"/>
      <inertia ixx="1.47858333672132E-07" ixy="1.18576994854538E-12" ixz="-4.80407376657536E-12" iyy="1.41914584192602E-07" iyz="4.17788434922029E-08" izz="4.21604565911276E-08"/>
    </inertial>
    <visual>
      <origin xyz="0 0 0" rpy="0 0 0"/>
      <geometry>
        <mesh filename="package://lhandpro_description/models/DH116S-R000-A1/meshes/finger33_link.STL"/>
      </geometry>
      <material name="">
        <color rgba="0.2 0.2 0.2 1"/>
      </material>
    </visual>
    <collision>
      <origin xyz="0 0 0" rpy="0 0 0"/>
      <geometry>
        <mesh filename="package://lhandpro_description/models/DH116S-R000-A1/meshes/finger33_link.STL"/>
      </geometry>
    </collision>
  </link>
  <joint name="finger33" type="fixed">
    <origin xyz="0 0 0" rpy="0 0 0"/>
    <parent link="finger32_link"/>
    <child link="finger33_link"/>
    <axis xyz="0 0 0"/>
  </joint>
  <link name="finger41_link">
    <inertial>
      <origin xyz="-9.92502562325998E-05 0.00187501159969453 0.014820900729557" rpy="0 0 0"/>
      <mass value="0.0041427825906401"/>
      <inertia ixx="3.6220134054032E-07" ixy="-1.65704576345153E-09" ixz="-5.59535256816269E-10" iyy="3.93202304061915E-07" iyz="1.16626470854897E-08" izz="1.57968682958101E-07"/>
    </inertial>
    <visual>
      <origin xyz="0 0 0" rpy="0 0 0"/>
      <geometry>
        <mesh filename="package://lhandpro_description/models/DH116S-R000-A1/meshes/finger41_link.STL"/>
      </geometry>
      <material name="">
        <color rgba="1 1 1 1"/>
      </material>
    </visual>
    <collision>
      <origin xyz="0 0 0" rpy="0 0 0"/>
      <geometry>
        <mesh filename="package://lhandpro_description/models/DH116S-R000-A1/meshes/finger41_link.STL"/>
      </geometry>
    </collision>
  </link>
  <joint name="finger41" type="revolute">
    <origin xyz="-0.00884629646917347 0.007306751562741 0.0874130612220856" rpy="0.185216698200614 -0.0252760066009568 0"/>
    <parent link="base_link"/>
    <child link="finger41_link"/>
    <axis xyz="1 0 0"/>
    <limit lower="0" upper="1.257" effort="0" velocity="0"/>
  </joint>
  <link name="finger42_link">
    <inertial>
      <origin xyz="-7.89219634561439E-05 0.00097321984233115 0.0112167692179996" rpy="0 0 0"/>
      <mass value="0.00382855237153465"/>
      <inertia ixx="3.99488238110434E-07" ixy="-1.85363448432404E-10" ixz="-4.12189120722601E-10" iyy="4.00190012613912E-07" iyz="5.18765070283196E-08" izz="6.93581584914543E-08"/>
    </inertial>
    <visual>
      <origin xyz="0 0 0" rpy="0 0 0"/>
      <geometry>
        <mesh filename="package://lhandpro_description/models/DH116S-R000-A1/meshes/finger42_link.STL"/>
      </geometry>
      <material name="">
        <color rgba="1 1 1 1"/>
      </material>
    </visual>
    <collision>
      <origin xyz="0 0 0" rpy="0 0 0"/>
      <geometry>
        <mesh filename="package://lhandpro_description/models/DH116S-R000-A1/meshes/finger42_link.STL"/>
      </geometry>
    </collision>
  </link>
  <joint name="finger42" type="revolute">
    <origin xyz="0 0 0.0295285227667386" rpy="0 0 0"/>
    <parent link="finger41_link"/>
    <child link="finger42_link"/>
    <axis xyz="1 0 0"/>
    <limit lower="0" upper="1.75" effort="0" velocity="0"/>
    <mimic joint="finger41" multiplier="1.40106471" offset="-0.0760281065"/>
  </joint>
  <link name="finger43_link">
    <inertial>
      <origin xyz="0.000145172504775415 -0.00439620819878777 0.019822139983784" rpy="0 0 0"/>
      <mass value="0.00194917989840034"/>
      <inertia ixx="9.24793211748131E-08" ixy="-2.25304567561179E-11" ixz="-1.15239273424032E-09" iyy="9.37057773401234E-08" iyz="2.34518680404736E-08" izz="3.12581553687104E-08"/>
    </inertial>
    <visual>
      <origin xyz="0 0 0" rpy="0 0 0"/>
      <geometry>
        <mesh filename="package://lhandpro_description/models/DH116S-R000-A1/meshes/finger43_link.STL"/>
      </geometry>
      <material name="">
        <color rgba="0.2 0.2 0.2 1"/>
      </material>
    </visual>
    <collision>
      <origin xyz="0 0 0" rpy="0 0 0"/>
      <geometry>
        <mesh filename="package://lhandpro_description/models/DH116S-R000-A1/meshes/finger43_link.STL"/>
      </geometry>
    </collision>
  </link>
  <joint name="finger43" type="fixed">
    <origin xyz="0 0 0" rpy="0 0 0"/>
    <parent link="finger42_link"/>
    <child link="finger43_link"/>
    <axis xyz="0 0 0"/>
  </joint>
  <link name="finger51_link">
    <inertial>
      <origin xyz="-2.33333913605971E-06 0.00181485062221548 0.0131392699022088" rpy="0 0 0"/>
      <mass value="0.00345037170327943"/>
      <inertia ixx="2.37940412354949E-07" ixy="-3.80727108476698E-12" ixz="8.69321923902387E-11" iyy="2.69111254422569E-07" iyz="7.24144543213933E-09" izz="1.35191102489079E-07"/>
    </inertial>
    <visual>
      <origin xyz="0 0 0" rpy="0 0 0"/>
      <geometry>
        <mesh filename="package://lhandpro_description/models/DH116S-R000-A1/meshes/finger51_link.STL"/>
      </geometry>
      <material name="">
        <color rgba="1 1 1 1"/>
      </material>
    </visual>
    <collision>
      <origin xyz="0 0 0" rpy="0 0 0"/>
      <geometry>
        <mesh filename="package://lhandpro_description/models/DH116S-R000-A1/meshes/finger51_link.STL"/>
      </geometry>
    </collision>
  </link>
  <joint name="finger51" type="revolute">
    <origin xyz="-0.0263133099109462 0.00562794981638235 0.0830420444966198" rpy="0.153405557961376 -0.116668550344774 0.149285285649185"/>
    <parent link="base_link"/>
    <child link="finger51_link"/>
    <axis xyz="1 0 0"/>
    <limit lower="0" upper="1.291" effort="0" velocity="0"/>
  </joint>
  <link name="finger52_link">
    <inertial>
      <origin xyz="-3.15300649285088E-05 0.00108071309102561 0.00848073574589434" rpy="0 0 0"/>
      <mass value="0.0034586827978682"/>
      <inertia ixx="2.5318219393825E-07" ixy="-5.26062638639635E-11" ixz="1.06905539796088E-09" iyy="2.54247652609832E-07" iyz="2.38936859610866E-08" izz="6.41400708772532E-08"/>
    </inertial>
    <visual>
      <origin xyz="0 0 0" rpy="0 0 0"/>
      <geometry>
        <mesh filename="package://lhandpro_description/models/DH116S-R000-A1/meshes/finger52_link.STL"/>
      </geometry>
      <material name="">
        <color rgba="1 1 1 1"/>
      </material>
    </visual>
    <collision>
      <origin xyz="0 0 0" rpy="0 0 0"/>
      <geometry>
        <mesh filename="package://lhandpro_description/models/DH116S-R000-A1/meshes/finger52_link.STL"/>
      </geometry>
    </collision>
  </link>
  <joint name="finger52" type="revolute">
    <origin xyz="0 0 0.0250241718362191" rpy="0 0 0"/>
    <parent link="finger51_link"/>
    <child link="finger52_link"/>
    <axis xyz="1 0 0"/>
    <limit lower="0" upper="1.75" effort="0" velocity="0"/>
    <mimic joint="finger51" multiplier="1.28966594" offset="-0.0841491377"/>
  </joint>
  <link name="finger53_link">
    <inertial>
      <origin xyz="-0.00010159715941721 -0.00420240434545652 0.0167623091483986" rpy="0 0 0"/>
      <mass value="0.00149578721592064"/>
      <inertia ixx="4.39306653069545E-08" ixy="5.60547792622162E-11" ixz="-2.47230752349555E-10" iyy="4.56160148535183E-08" iyz="1.05043396073308E-08" izz="2.11073455747021E-08"/>
    </inertial>
    <visual>
      <origin xyz="0 0 0" rpy="0 0 0"/>
      <geometry>
        <mesh filename="package://lhandpro_description/models/DH116S-R000-A1/meshes/finger53_link.STL"/>
      </geometry>
      <material name="">
        <color rgba="0.2 0.2 0.2 1"/>
      </material>
    </visual>
    <collision>
      <origin xyz="0 0 0" rpy="0 0 0"/>
      <geometry>
        <mesh filename="package://lhandpro_description/models/DH116S-R000-A1/meshes/finger53_link.STL"/>
      </geometry>
    </collision>
  </link>
  <joint name="finger53" type="fixed">
    <origin xyz="0 0 0" rpy="0 0 0"/>
    <parent link="finger52_link"/>
    <child link="finger53_link"/>
    <axis xyz="0 0 0"/>
  </joint>
</robot>