<?xml version="1.0" encoding="utf-8"?>
<!--
  MuJoCo MJCF model for DH116S-L000-A1 Dexterous Hand (Left)
  ============================================================
  Converted from SolidWorks URDF export.

  ── 关节分类 ──────────────────────────────────────────────────
  主动关节 (6 个，独立 DOF，有执行器):
    finger11 : 拇指摆动    (MCP ab/adduction)
    finger12 : 拇指屈曲    (MCP flexion)
    finger21 : 食指 MCP
    finger31 : 中指 MCP
    finger41 : 无名指 MCP
    finger51 : 小拇指 MCP

  从动关节 (5 个，equality 约束，被动跟随):
    finger13 : 拇指 IP      跟随 finger12
    finger22 : 食指 PIP     跟随 finger21
    finger32 : 中指 PIP     跟随 finger31
    finger42 : 无名指 PIP   跟随 finger41
    finger52 : 小拇指 PIP   跟随 finger51

  固连体 (5 个，和父连杆完全固连，无关节):
    finger14_link : 拇指橡胶垫   (rigidly attached to finger13_link)
    finger23_link : 食指橡胶垫   (rigidly attached to finger22_link)
    finger33_link : 中指橡胶垫   (rigidly attached to finger32_link)
    finger43_link : 无名指橡胶垫 (rigidly attached to finger42_link)
    finger53_link : 小拇指橡胶垫 (rigidly attached to finger52_link)

  ── Equality 多项式说明 ──────────────────────────────────────
  原始公式 (单位: 角度°):
    大拇指:  y = -0.0008x² + 0.929x  - 0.8639
    食指:    y =  0.0067x² + 0.8847x + 2.1926
    中指:    y =  0.0076x² + 0.8485x + 2.0597
    无名指:  y =  0.0079x² + 0.8321x + 2.4732
    小拇指:  y =  0.0075x² + 0.7349x + 2.0181

  MuJoCo polycoef 换算 (单位: 弧度 rad):
    y_deg = C0 + C1*x_deg + C2*x_deg²
    y_rad = C0*(π/180) + C1*x_rad + C2*(180/π)*x_rad²
    polycoef = "C0*(π/180)  C1  C2*(180/π)  0  0"
--><mujoco model="DH116S-L000-A1">

  <compiler angle="radian" meshdir="../meshes" eulerseq="XYZ" autolimits="true"/>
  <option gravity="0 0 -9.81" timestep="0.002" iterations="100"/>

  <default>
    <!-- 统一关节阻尼与虚拟惯量，配合位置执行器形成过阻尼响应，减小摇晃 -->
    <joint type="hinge" damping="2.0" armature="0.01" frictionloss="0"/>
    <!-- 默认关闭接触参与；需要接触的被动指节/胶垫在各自 geom 上单独覆盖 -->
    <geom condim="4" friction="1.0 0.005 0.001" contype="0" conaffinity="0"/>
    <!-- equality: 减小 solref[0] 时间常数 → 约束更硬，残差更小 -->
    <equality solref="0.004 1" solimp="0.9 0.99 0.001 0.5 2"/>
  </default>

  <!-- ==================== 网格资源 ==================== -->
  <asset>
    <mesh name="base_link" file="base_link.STL"/>
    <mesh name="finger11_link" file="finger11_link.STL"/>
    <mesh name="finger12_link" file="finger12_link.STL"/>
    <mesh name="finger13_link" file="finger13_link.STL"/>
    <mesh name="finger14_link" file="finger14_link.STL"/>
    <mesh name="finger21_link" file="finger21_link.STL"/>
    <mesh name="finger22_link" file="finger22_link.STL"/>
    <mesh name="finger23_link" file="finger23_link.STL"/>
    <mesh name="finger31_link" file="finger31_link.STL"/>
    <mesh name="finger32_link" file="finger32_link.STL"/>
    <mesh name="finger33_link" file="finger33_link.STL"/>
    <mesh name="finger41_link" file="finger41_link.STL"/>
    <mesh name="finger42_link" file="finger42_link.STL"/>
    <mesh name="finger43_link" file="finger43_link.STL"/>
    <mesh name="finger51_link" file="finger51_link.STL"/>
    <mesh name="finger52_link" file="finger52_link.STL"/>
    <mesh name="finger53_link" file="finger53_link.STL"/>
  </asset>

  <!-- ==================== 运动体树 ==================== -->
  <worldbody>

    <!-- 手掌基座（焊死在世界坐标系） -->
    <body name="base_link" pos="0 0 0">
      <geom name="base_link" type="mesh" mesh="base_link" rgba="0.85 0.85 0.85 1"/>
      <inertial pos="0.000544524993373097 -0.00750466902165473 0.0473989905049091" mass="0.106661851888605" fullinertia="4.60958938891066E-05 6.68395890156874E-05 2.99930119861266E-05 -4.13539236103623E-08 1.98096595874894E-07 1.57819216681043E-06"/>

      <!-- ===== 手指 1：大拇指 (Thumb) ===== -->

      <!--
        finger11: 主动 — 拇指摆动 (MCP ab/adduction)
        绕 +Z 轴，范围 0~1.588 rad，独立执行器驱动
      -->
      <body name="finger11_link" pos="0.0193521365394396 0.00780520239676655 0.0343200230340877" euler="0 5.66182786981891E-05 0">
        <joint name="finger11" axis="0 0 1" range="0 1.588"/>
        <geom name="finger11_link" type="mesh" mesh="finger11_link" rgba="0.9 0.9 0.9 1"/>
        <inertial pos="0.00880711190023678 0.00163343220926083 0.00136775413572365" mass="0.00703896093413542" fullinertia="9.90699426372342E-07 9.57269339123916E-07 2.86923099019118E-07 -1.94396154626989E-08 -9.77092169793553E-08 -4.37556082720952E-08"/>

        <!--
          finger12: 主动 — 拇指 MCP 屈曲 (MCP flexion)
          绕 -X 轴，范围 0~1.030 rad，独立执行器驱动
        -->
        <body name="finger12_link" pos="0.0149999999999999 0.00241716818236522 0.00671430739572605" euler="0.914542570706424 0.26179938779915 1.5707963267949">
          <joint name="finger12" axis="-1 0 0" range="0 1.030"/>
          <geom name="finger12_link" type="mesh" mesh="finger12_link" rgba="0.9 0.9 0.9 1"/>
          <inertial pos="0.000626165204877099 -0.00814581305344735 0.020646424515226" mass="0.00572071000157471" fullinertia="1.08317641871166E-06 1.26897009959513E-06 5.51662991743827E-07 1.92569888242211E-09 -1.00701276813813E-08 2.85476025728995E-07"/>

          <!--
            finger13: 从动 — 拇指 IP (interphalangeal)
            绕 -X 轴，由 equality 约束跟随 finger12 (MCP flexion)
            原始公式(°): y = -0.0008x² + 0.929x - 0.8639
            polycoef(rad): [-0.015082, 0.929, -0.045837, 0, 0]
          -->
          <body name="finger13_link" pos="0.000907073874635978 -0.012631430230703 0.0382111085733653" euler="0.320192464474519 0.0133797340704482 0.0102567262059099">
            <joint name="finger13" axis="-1 0 0" range="0 1.13"/>
            <geom name="finger13_link" type="mesh" mesh="finger13_link" rgba="0.9 0.9 0.9 1" contype="1" conaffinity="1"/>
            <inertial pos="2.07998097687193E-05 -0.000735323631083362 0.00878868708953141" mass="0.00512347195060515" fullinertia="2.40948357970622E-07 3.07751224311247E-07 1.6169760241038E-07 -5.09925158040025E-10 -9.60120677468293E-10 -7.35275312906535E-09"/>

            <!--
              finger14_link: 拇指橡胶垫
              无关节，完全固连到 finger13_link，随 IP 一同运动
            -->
            <body name="finger14_link" pos="0 0 0" euler="0 0 0">
              <geom name="finger14_link" type="mesh" mesh="finger14_link" rgba="0.2 0.2 0.2 1" contype="1" conaffinity="1"/>
              <inertial pos="-3.82292380026773E-06 0.00466183376594907 0.0121285985080434" mass="0.00240509776372723" fullinertia="6.51447989844391E-08 9.97646532599649E-08 5.51927068070888E-08 -3.50977911008853E-10 -5.25932270434576E-10 3.06515732443468E-09"/>
            </body>

          </body>
        </body>
      </body>

      <!-- ===== 手指 2：食指 (Index) ===== -->

      <!--
        finger21: 主动 — 食指 MCP
        绕 -X 轴，范围 0~1.257 rad，独立执行器驱动
      -->
      <body name="finger21_link" pos="0.0263221667373393 -0.00532638133131497 0.0839088174238425" euler="0.0157127180588976 0.0976603903613511 0.159786795598776">
        <joint name="finger21" axis="-1 0 0" range="0 1.257"/>
        <geom name="finger21_link" type="mesh" mesh="finger21_link" rgba="0.9 0.9 0.9 1"/>
        <inertial pos="3.48658519827572E-06 0.000948250837583636 0.0145873180381056" mass="0.00393802264883532" fullinertia="3.15961467581521E-07 3.37002395494748E-07 1.60677749968883E-07 -4.20917811183589E-11 -5.78570860505374E-11 -4.22831681499364E-08"/>

        <!--
          finger22: 从动 — 食指 PIP
          绕 -X 轴，由 equality 约束跟随 finger21 (MCP)
          原始公式(°): y = 0.0067x² + 0.8847x + 2.1926
          polycoef(rad): [0.038265, 0.8847, 0.383882, 0, 0]
        -->
        <body name="finger22_link" pos="0 0.00510326179486572 0.027558142915563" euler="-0.183107378899691 0 0">
          <joint name="finger22" axis="-1 0 0" range="0 1.75"/>
          <geom name="finger22_link" type="mesh" mesh="finger22_link" rgba="0.9 0.9 0.9 1" contype="1" conaffinity="1"/>
          <inertial pos="3.4802021511543E-05 -0.0013486986363819 0.0109130316550571" mass="0.00359512240318104" fullinertia="3.71466761108892E-07 3.74376153910801E-07 6.27182251872621E-08 -1.29499027210776E-10 -2.16937317653213E-09 -4.18381122144735E-08"/>

          <!--
            finger23_link: 食指橡胶垫
            无关节，完全固连到 finger22_link，随 PIP 一同运动
          -->
          <body name="finger23_link" pos="0 0 0" euler="0 0 0">
            <geom name="finger23_link" type="mesh" mesh="finger23_link" rgba="0.2 0.2 0.2 1" contype="1" conaffinity="1"/>
            <inertial pos="7.82510692590443E-05 0.00383960022189855 0.0191163509786596" mass="0.00194918551000528" fullinertia="9.24802884509747E-08 9.4711884333877E-08 3.02506375048604E-08 2.86384855175092E-11 -2.8430749674239E-11 -2.20774521775598E-08"/>
          </body>

        </body>
      </body>

      <!-- ===== 手指 3：中指 (Middle) ===== -->

      <!--
        finger31: 主动 — 中指 MCP
        绕 -X 轴，范围 0~1.257 rad，独立执行器驱动
      -->
      <body name="finger31_link" pos="0.00853056012195752 -0.00653399721710813 0.08818546795159" euler="0.000712944465730327 0.0134076578043506 0.0531259881623533">
        <joint name="finger31" axis="-1 0 0" range="0 1.257"/>
        <geom name="finger31_link" type="mesh" mesh="finger31_link" rgba="0.9 0.9 0.9 1"/>
        <inertial pos="2.43928457896447E-06 0.00125405351222651 0.0166476625726954" mass="0.00465629805037929" fullinertia="4.64033183836396E-07 4.82279099347931E-07 1.92342304939614E-07 -6.96661919362374E-11 -4.25124779854874E-11 -6.61666793058518E-08"/>

        <!--
          finger32: 从动 — 中指 PIP
          绕 -X 轴，由 equality 约束跟随 finger31 (MCP)
          原始公式(°): y = 0.0076x² + 0.8485x + 2.0597
          polycoef(rad): [0.035946, 0.8485, 0.435448, 0, 0]
        -->
        <body name="finger32_link" pos="0 0.00597179476535116 0.031978135864213" euler="0 0 0">
          <joint name="finger32" axis="-1 0 0" range="0 1.75"/>
          <geom name="finger32_link" type="mesh" mesh="finger32_link" rgba="0.9 0.9 0.9 1" contype="1" conaffinity="1"/>
          <inertial pos="5.01008760783739E-07 0.00197036044989129 0.0124117968912229" mass="0.00396494093318317" fullinertia="5.13626527975483E-07 4.59220436955248E-07 1.2884536852607E-07 -6.50187509823643E-10 -1.427207122136E-09 -1.60262467986869E-07"/>

          <!--
            finger33_link: 中指橡胶垫
            无关节，完全固连到 finger32_link，随 PIP 一同运动
          -->
          <body name="finger33_link" pos="0 0 0" euler="0 0 0">
            <geom name="finger33_link" type="mesh" mesh="finger33_link" rgba="0.2 0.2 0.2 1" contype="1" conaffinity="1"/>
            <inertial pos="-8.36698258038782E-07 0.00923385266648058 0.019768310971155" mass="0.00227281439382211" fullinertia="1.47849455761078E-07 1.24393141276961E-07 5.96778300199862E-08 -3.47553525565444E-12 4.73897847071394E-12 -5.64492431895065E-08"/>
          </body>

        </body>
      </body>

      <!-- ===== 手指 4：无名指 (Ring) ===== -->

      <!--
        finger41: 主动 — 无名指 MCP
        绕 -X 轴，范围 0~1.257 rad，独立执行器驱动
      -->
      <body name="finger41_link" pos="-0.00888762654492145 -0.00728133879903732 0.087396405615583" euler="0.00302662499820262 -0.0615538222955632 -0.0491619519178472">
        <joint name="finger41" axis="-1 0 0" range="0 1.257"/>
        <geom name="finger41_link" type="mesh" mesh="finger41_link" rgba="0.9 0.9 0.9 1"/>
        <inertial pos="2.05886925985777E-06 0.00090785719008161 0.0149119186393758" mass="0.00414279060803409" fullinertia="3.62106671626076E-07 3.80908507437567E-07 1.70352561515995E-07 -5.103578461109E-11 -3.5507325901272E-11 -5.38270721397437E-08"/>

        <!--
          finger42: 从动 — 无名指 PIP
          绕 -X 轴，由 equality 约束跟随 finger41 (MCP)
          原始公式(°): y = 0.0079x² + 0.8321x + 2.4732
          polycoef(rad): [0.043170, 0.8321, 0.452637, 0, 0]
        -->
        <body name="finger42_link" pos="0 0.0054849861571379 0.0290146270636347" euler="0 0 0">
          <joint name="finger42" axis="-1 0 0" range="0 1.75"/>
          <geom name="finger42_link" type="mesh" mesh="finger42_link" rgba="0.9 0.9 0.9 1" contype="1" conaffinity="1"/>
          <inertial pos="2.84390017567804E-05 0.00112452617014073 0.0112028625820284" mass="0.00382854887772676" fullinertia="3.99470431936905E-07 3.69872009847734E-07 9.9693004199021E-08 -5.67931499263376E-10 -2.20703573764736E-09 -1.08637975960505E-07"/>

          <!--
            finger43_link: 无名指橡胶垫
            无关节，完全固连到 finger42_link，随 PIP 一同运动
          -->
          <body name="finger43_link" pos="0 0 0" euler="0 0 0">
            <geom name="finger43_link" type="mesh" mesh="finger43_link" rgba="0.2 0.2 0.2 1" contype="1" conaffinity="1"/>
            <inertial pos="8.26566494929459E-05 0.0080032742682453 0.0186602518602537" mass="0.00194917712642498" fullinertia="9.24798762660555E-08 8.29792742143362E-08 4.19842737997981E-08 2.85735039571308E-11 -6.99992684169389E-11 -3.32575242019174E-08"/>
          </body>

        </body>
      </body>

      <!-- ===== 手指 5：小拇指 (Pinky) ===== -->

      <!--
        finger51: 主动 — 小拇指 MCP
        绕 -X 轴，范围 0~1.291 rad，独立执行器驱动
      -->
      <body name="finger51_link" pos="-0.0264481824708094 -0.0055488670962835 0.0829799586736383" euler="-0.153756050317575 -0.150571871776981 -0.147041448694914">
        <joint name="finger51" axis="-1 0 0" range="0 1.291"/>
        <geom name="finger51_link" type="mesh" mesh="finger51_link" rgba="0.9 0.9 0.9 1"/>
        <inertial pos="2.41601579473172E-06 -0.00181484079250304 0.013139258005117" mass="0.00345036527036827" fullinertia="2.37942641790154E-07 2.69109132278489E-07 1.35190326045818E-07 -5.32043409424851E-12 -8.79535456047855E-11 -7.2412901851165E-09"/>

        <!--
          finger52: 从动 — 小拇指 PIP
          绕 -X 轴，由 equality 约束跟随 finger51 (MCP)
          原始公式(°): y = 0.0075x² + 0.7349x + 2.0181
          polycoef(rad): [0.035218, 0.7349, 0.429718, 0, 0]
        -->
        <body name="finger52_link" pos="0 0 0.0250241718362191" euler="0.175969487717828 0 0">
          <joint name="finger52" axis="-1 0 0" range="0 1.75"/>
          <geom name="finger52_link" type="mesh" mesh="finger52_link" rgba="0.9 0.9 0.9 1" contype="1" conaffinity="1"/>
          <inertial pos="3.15909470655629E-05 0.000420621153260112 0.00853927270244959" mass="0.00345865291103541" fullinertia="2.5318519633019E-07 2.40188074028539E-07 7.82039203203485E-08 -2.39436526506233E-10 -1.04452087253161E-09 -5.52012080873732E-08"/>

          <!--
            finger53_link: 小拇指橡胶垫
            无关节，完全固连到 finger52_link，随 PIP 一同运动
          -->
          <body name="finger53_link" pos="0 0 0" euler="0 0 0">
            <geom name="finger53_link" type="mesh" mesh="finger53_link" rgba="0.2 0.2 0.2 1" contype="1" conaffinity="1"/>
            <inertial pos="0.000103786229699587 0.00707344092632247 0.0157672382146304" mass="0.00149700207994512" fullinertia="4.39757858831556E-08 4.12565550714953E-08 2.55293698498865E-08 9.14180234774832E-11 2.33368010245624E-10 -1.41132607567297E-08"/>
          </body>

        </body>
      </body>

    </body>
  </worldbody>

  <!-- ==================== 主从关节联动约束 ====================
    MuJoCo polycoef 语法:
      joint1(从动) = c[0] + c[1]*joint2(主动) + c[2]*joint2² + c[3]*joint2³ + c[4]*joint2⁴

    单位换算 (原始公式为角度°，MuJoCo 内部用弧度 rad):
      y_deg = C0 + C1*x_deg + C2*x_deg²
      c[0] = C0 × (π/180)
      c[1] = C1
      c[2] = C2 × (180/π)
    ┌──────────┬──────────────────────────────────────────────────────────┐
    │ 手指     │ 原始公式 (°)                  → polycoef (rad)          │
    ├──────────┼──────────────────────────────────────────────────────────┤
    │ 大拇指   │ -0.0008x²+0.929x-0.8639  → -0.015082 0.929 -0.045837   │
    │ 食指     │  0.0067x²+0.8847x+2.1926 →  0.038265 0.8847  0.383882  │
    │ 中指     │  0.0076x²+0.8485x+2.0597 →  0.035946 0.8485  0.435448  │
    │ 无名指   │  0.0079x²+0.8321x+2.4732 →  0.043170 0.8321  0.452637  │
    │ 小拇指   │  0.0075x²+0.7349x+2.0181 →  0.035218 0.7349  0.429718  │
    └──────────┴──────────────────────────────────────────────────────────┘
  ======================================================== -->
  <equality>
    <!-- 大拇指 IP (finger13, 从动) 跟随 MCP flexion (finger12, 主动) -->
    <joint name="eq_thumb" joint1="finger13" joint2="finger12" polycoef="-0.015082 0.929 -0.045837 0 0"/>

    <!-- 食指 PIP (finger22, 从动) 跟随 MCP (finger21, 主动) -->
    <joint name="eq_index" joint1="finger22" joint2="finger21" polycoef="0.038265 0.8847 0.383882 0 0"/>

    <!-- 中指 PIP (finger32, 从动) 跟随 MCP (finger31, 主动) -->
    <joint name="eq_middle" joint1="finger32" joint2="finger31" polycoef="0.035946 0.8485 0.435448 0 0"/>

    <!-- 无名指 PIP (finger42, 从动) 跟随 MCP (finger41, 主动) -->
    <joint name="eq_ring" joint1="finger42" joint2="finger41" polycoef="0.043170 0.8321 0.452637 0 0"/>

    <!-- 小拇指 PIP (finger52, 从动) 跟随 MCP (finger51, 主动) -->
    <joint name="eq_pinky" joint1="finger52" joint2="finger51" polycoef="0.035218 0.7349 0.429718 0 0"/>
  </equality>

  <!-- ==================== 执行器（6 个主动自由度）====================
    仅对主动关节添加执行器，从动关节 (finger13/22/32/42/52) 由 equality
    自动驱动，橡胶垫固连体无需执行器。
    kp=50  : 位置刚度（弹簧）
    kv=2.0 : 速度阻尼（速度反馈，与 joint damping 共同决定阻尼比）
    阻尼比 ζ = (kv + damping) / (2√(kp × armature))
             = (2.0 + 2.0) / (2√(50 × 0.01)) ≈ 2.83  → 过阻尼，无摇晃
  ======================================================== -->
  <actuator>
    <!-- 大拇指: 2 个主动 DOF -->
    <position name="act_finger11" joint="finger11" kp="50" kv="2.0" ctrlrange="0 1.588"/>
    <position name="act_finger12" joint="finger12" kp="50" kv="2.0" ctrlrange="0 1.030"/>

    <!-- 食指: 1 个主动 DOF (PIP 由 equality 驱动) -->
    <position name="act_finger21" joint="finger21" kp="50" kv="2.0" ctrlrange="0 1.257"/>

    <!-- 中指: 1 个主动 DOF -->
    <position name="act_finger31" joint="finger31" kp="50" kv="2.0" ctrlrange="0 1.257"/>

    <!-- 无名指: 1 个主动 DOF -->
    <position name="act_finger41" joint="finger41" kp="50" kv="2.0" ctrlrange="0 1.257"/>

    <!-- 小拇指: 1 个主动 DOF -->
    <position name="act_finger51" joint="finger51" kp="50" kv="2.0" ctrlrange="0 1.291"/>
  </actuator>

</mujoco>